Workbook

Sheet StudendEnroll
A1: Name | B1: Surname | C1: email | D1: Class | E1: Certification Status | F1: Course | G1: Learners | H1: Passed | I1: Failed To Pass
A2: John | B2: Makaron | C2: =A2&MID(B2,2,2)&"@gmail.com" -> Johnak@gmail.com | D2: Physics1 | E2: =_xlfn.XLOOKUP(C2,StudentTracker!$C$2:$C$44,StudentTracker!$J$2:$J$44) -> Excellent | F2: Maths1 | G2: =COUNTIF($D$2:$D$444,$F2) -> 15 | H2: =COUNTIFS(D2:D44,F2,E2:E44,"<>Failed") -> 13 | I2: =COUNTIFS(D2:D44,F2,E2:E44,"Failed") -> 2
A3: Elvis | B3: Bond | C3: =A3&MID(B3,2,2)&"@gmail.com" -> Elvison@gmail.com | D3: Maths1 | E3: =_xlfn.XLOOKUP(C3,StudentTracker!$C$2:$C$44,StudentTracker!$J$2:$J$44) -> Excellent | F3: Physics1 | G3: =COUNTIF($D$2:$D$444,$F3) -> 13 | H3: =COUNTIFS(D3:D45,F3,E3:E45,"<>Failed") -> 10 | I3: =COUNTIFS(D3:D45,F3,E3:E45,"Failed") -> 2
A4: Mary | B4: Gas | C4: =A4&MID(B4,2,2)&"@gmail.com" -> Maryas@gmail.com | D4: Maths1 | E4: =_xlfn.XLOOKUP(C4,StudentTracker!$C$2:$C$44,StudentTracker!$J$2:$J$44) -> Failed | F4: English Language | G4: =COUNTIF($D$2:$D$444,$F4) -> 15 | H4: =COUNTIFS(D4:D46,F4,E4:E46,"<>Failed") -> 12 | I4: =COUNTIFS(D4:D46,F4,E4:E46,"Failed") -> 3
A5: Olivia | B5: Matt | C5: =A5&MID(B5,2,2)&"@gmail.com" -> Oliviaat@gmail.com | D5: Physics1 | E5: =_xlfn.XLOOKUP(C5,StudentTracker!$C$2:$C$44,StudentTracker!$J$2:$J$44) -> Good
A6: Robert | B6: Hus | C6: =A6&MID(B6,2,2)&"@gmail.com" -> Robertus@gmail.com | D6: Maths1 | E6: =_xlfn.XLOOKUP(C6,StudentTracker!$C$2:$C$44,StudentTracker!$J$2:$J$44) -> Excellent
A7: Omar | B7: Kasim | C7: =A7&MID(B7,2,2)&"@gmail.com" -> Omaras@gmail.com | D7: Maths1 | E7: =_xlfn.XLOOKUP(C7,StudentTracker!$C$2:$C$44,StudentTracker!$J$2:$J$44) -> Pass
A8: Diana | B8: Pinto | C8: =A8&MID(B8,2,2)&"@gmail.com" -> Dianain@gmail.com | D8: Physics1 | E8: =_xlfn.XLOOKUP(C8,StudentTracker!$C$2:$C$44,StudentTracker!$J$2:$J$44) -> Failed
A9: Denis | B9: Rodman | C9: =A9&MID(B9,2,2)&"@gmail.com" -> Denisod@gmail.com | D9: Maths1 | E9: =_xlfn.XLOOKUP(C9,StudentTracker!$C$2:$C$44,StudentTracker!$J$2:$J$44) -> Good
A10: Kate | B10: Potter | C10: =A10&MID(B10,2,2)&"@gmail.com" -> Kateot@gmail.com | D10: Physics1 | E10: =_xlfn.XLOOKUP(C10,StudentTracker!$C$2:$C$44,StudentTracker!$J$2:$J$44) -> Excellent
A11: Manny | B11: Pac | C11: =A11&MID(B11,2,2)&"@gmail.com" -> Mannyac@gmail.com | D11: Physics1 | E11: =_xlfn.XLOOKUP(C11,StudentTracker!$C$2:$C$44,StudentTracker!$J$2:$J$44) -> Pass
A12: Katy | B12: Perri | C12: =A12&MID(B12,2,2)&"@gmail.com" -> Katyer@gmail.com | D12: Physics1 | E12: =_xlfn.XLOOKUP(C12,StudentTracker!$C$2:$C$44,StudentTracker!$J$2:$J$44) -> Excellent
A13: Antony | B13: Ward | C13: =A13&MID(B13,2,2)&"@gmail.com" -> Antonyar@gmail.com | D13: Physics1 | E13: =_xlfn.XLOOKUP(C13,StudentTracker!$C$2:$C$44,StudentTracker!$J$2:$J$44) -> Good
A14: Billy | B14: Sane | C14: =A14&MID(B14,2,2)&"@gmail.com" -> Billyan@gmail.com | D14: Physics1 | E14: =_xlfn.XLOOKUP(C14,StudentTracker!$C$2:$C$44,StudentTracker!$J$2:$J$44) -> Pass
A15: Ronald | B15: Connan | C15: =A15&MID(B15,2,2)&"@gmail.com" -> Ronaldon@gmail.com | D15: Physics1 | E15: =_xlfn.XLOOKUP(C15,StudentTracker!$C$2:$C$44,StudentTracker!$J$2:$J$44) -> Good
A16: John | B16: Baderas | C16: =A16&MID(B16,2,2)&"@gmail.com" -> Johnad@gmail.com | D16: Maths1 | E16: =_xlfn.XLOOKUP(C16,StudentTracker!$C$2:$C$44,StudentTracker!$J$2:$J$44) -> Excellent
... A44: Kostas | B44: Loukas | C44: =A44&MID(B44,2,2)&"@gmail.com" -> Kostasou@gmail.com | D44: Physics1 | E44: =_xlfn.XLOOKUP(C44,StudentTracker!$C$2:$C$44,StudentTracker!$J$2:$J$44) -> Excellent

Sheet StudentTracker
A1: Name | B1: Surname | C1: email | D1: Class | E1: Attendance | F1: 1st test score | G1: 2nd test score | H1: Final Assignment Completed | I1: Certificate Score | J1: Certificate Rank
A2: =StudendEnroll!A2 -> John | B2: =StudendEnroll!B2 -> Makaron | C2: =StudendEnroll!C2 -> Johnak@gmail.com | D2: =StudendEnroll!D2 -> Physics1 | E2: =IF(D2=$N$3,(_xlfn.XLOOKUP(C2,'Physics1.DailyAttendance'!$D$2:$D$14,'Physics1.DailyAttendance'!$R$2:$R$14)),_xlfn.XLOOKUP(C2,'Maths1.DailyAttendance'!$D$2:$D$16,'Maths1.DailyAttendance'!$R$2:$R$16,_xlfn.XLOOKUP(C2,'English Language'!$D$2:$D$16,'English Language'!$R$2:$R$16))) -> 0.8 | F2: =IF(D2=$N$3,(_xlfn.XLOOKUP(C2,'Physics1.DailyAttendance'!$D$2:$D$16,'Physics1.DailyAttendance'!$S$2:$S$16)),_xlfn.XLOOKUP(C2,'Maths1.DailyAttendance'!$D$2:$D$16,'Maths1.DailyAttendance'!$S$2:$S$16,_xlfn.XLOOKUP(C2,'English Language'!D$2:$D$16,'English Language'!$S$2:$S$16))) -> 85 | G2: =IF(D2=$N$3,(_xlfn.XLOOKUP(C2,'Physics1.DailyAttendance'!$D$2:$D$16,'Physics1.DailyAttendance'!$T$2:$T$16)),_xlfn.XLOOKUP(C2,'Maths1.DailyAttendance'!$D$2:$D$16,'Maths1.DailyAttendance'!$T$2:$T$16,_xlfn.XLOOKUP(C2,'English Language'!$D$2:$D$16,'English Language'!$T$2:$T$16))) -> 87 | H2: =IF(D2=$N$3,(_xlfn.XLOOKUP(C2,'Physics1.DailyAttendance'!$D$2:$D$16,'Physics1.DailyAttendance'!$U$2:$U$16)),_xlfn.XLOOKUP(C2,'Maths1.DailyAttendance'!$D$2:$D$16,'Maths1.DailyAttendance'!$U$2:$U$16,_xlfn.XLOOKUP(C2,'English Language'!$D$2:F$16,'English Language'!$U$2:$U$16))) -> Yes | I2: =(E2*40)+F2*0.15+G2*0.2+(IF(H2="Yes",25,0)) -> 87.15 | J2: =IF(I2>87,"Excellent",IF(I2<70,"Failed",IF(I2>77,"Good","Pass"))) -> Excellent | N2: Classes | P2: Certification Score
A3: =StudendEnroll!A3 -> Elvis | B3: =StudendEnroll!B3 -> Bond | C3: =StudendEnroll!C3 -> Elvison@gmail.com | D3: =StudendEnroll!D3 -> Maths1 | E3: =IF(D3=$N$3,(_xlfn.XLOOKUP(C3,'Physics1.DailyAttendance'!$D$2:$D$14,'Physics1.DailyAttendance'!$R$2:$R$14)),_xlfn.XLOOKUP(C3,'Maths1.DailyAttendance'!$D$2:$D$16,'Maths1.DailyAttendance'!$R$2:$R$16,_xlfn.XLOOKUP(C3,'English Language'!$D$2:$D$16,'English Language'!$R$2:$R$16))) -> 0.9 | F3: =IF(D3=$N$3,(_xlfn.XLOOKUP(C3,'Physics1.DailyAttendance'!$D$2:$D$16,'Physics1.DailyAttendance'!$S$2:$S$16)),_xlfn.XLOOKUP(C3,'Maths1.DailyAttendance'!$D$2:$D$16,'Maths1.DailyAttendance'!$S$2:$S$16,_xlfn.XLOOKUP(C3,'English Language'!D$2:$D$16,'English Language'!$S$2:$S$16))) -> 96 | G3: =IF(D3=$N$3,(_xlfn.XLOOKUP(C3,'Physics1.DailyAttendance'!$D$2:$D$16,'Physics1.DailyAttendance'!$T$2:$T$16)),_xlfn.XLOOKUP(C3,'Maths1.DailyAttendance'!$D$2:$D$16,'Maths1.DailyAttendance'!$T$2:$T$16,_xlfn.XLOOKUP(C3,'English Language'!$D$2:$D$16,'English Language'!$T$2:$T$16))) -> 88 | H3: =IF(D3=$N$3,(_xlfn.XLOOKUP(C3,'Physics1.DailyAttendance'!$D$2:$D$16,'Physics1.DailyAttendance'!$U$2:$U$16)),_xlfn.XLOOKUP(C3,'Maths1.DailyAttendance'!$D$2:$D$16,'Maths1.DailyAttendance'!$U$2:$U$16,_xlfn.XLOOKUP(C3,'English Language'!$D$2:F$16,'English Language'!$U$2:$U$16))) -> Yes | I3: =(E3*40)+F3*0.15+G3*0.2+(IF(H3="Yes",25,0)) -> 93 | J3: =IF(I3>87,"Excellent",IF(I3<70,"Failed",IF(I3>77,"Good","Pass"))) -> Excellent | N3: Physics1 | X3: Points
A4: =StudendEnroll!A4 -> Mary | B4: =StudendEnroll!B4 -> Gas | C4: =StudendEnroll!C4 -> Maryas@gmail.com | D4: =StudendEnroll!D4 -> Maths1 | E4: =IF(D4=$N$3,(_xlfn.XLOOKUP(C4,'Physics1.DailyAttendance'!$D$2:$D$14,'Physics1.DailyAttendance'!$R$2:$R$14)),_xlfn.XLOOKUP(C4,'Maths1.DailyAttendance'!$D$2:$D$16,'Maths1.DailyAttendance'!$R$2:$R$16,_xlfn.XLOOKUP(C4,'English Language'!$D$2:$D$16,'English Language'!$R$2:$R$16))) -> 0.9 | F4: =IF(D4=$N$3,(_xlfn.XLOOKUP(C4,'Physics1.DailyAttendance'!$D$2:$D$16,'Physics1.DailyAttendance'!$S$2:$S$16)),_xlfn.XLOOKUP(C4,'Maths1.DailyAttendance'!$D$2:$D$16,'Maths1.DailyAttendance'!$S$2:$S$16,_xlfn.XLOOKUP(C4,'English Language'!D$2:$D$16,'English Language'!$S$2:$S$16))) -> 55 | G4: =IF(D4=$N$3,(_xlfn.XLOOKUP(C4,'Physics1.DailyAttendance'!$D$2:$D$16,'Physics1.DailyAttendance'!$T$2:$T$16)),_xlfn.XLOOKUP(C4,'Maths1.DailyAttendance'!$D$2:$D$16,'Maths1.DailyAttendance'!$T$2:$T$16,_xlfn.XLOOKUP(C4,'English Language'!$D$2:$D$16,'English Language'!$T$2:$T$16))) -> 66 | H4: =IF(D4=$N$3,(_xlfn.XLOOKUP(C4,'Physics1.DailyAttendance'!$D$2:$D$16,'Physics1.DailyAttendance'!$U$2:$U$16)),_xlfn.XLOOKUP(C4,'Maths1.DailyAttendance'!$D$2:$D$16,'Maths1.DailyAttendance'!$U$2:$U$16,_xlfn.XLOOKUP(C4,'English Language'!$D$2:F$16,'English Language'!$U$2:$U$16))) -> No | I4: =(E4*40)+F4*0.15+G4*0.2+(IF(H4="Yes",25,0)) -> 57.45 | J4: =IF(I4>87,"Excellent",IF(I4<70,"Failed",IF(I4>77,"Good","Pass"))) -> Failed | N4: Maths1 | Q4: Attendance | X4: 40
A5: =StudendEnroll!A5 -> Olivia | B5: =StudendEnroll!B5 -> Matt | C5: =StudendEnroll!C5 -> Oliviaat@gmail.com | D5: =StudendEnroll!D5 -> Physics1 | E5: =IF(D5=$N$3,(_xlfn.XLOOKUP(C5,'Physics1.DailyAttendance'!$D$2:$D$14,'Physics1.DailyAttendance'!$R$2:$R$14)),_xlfn.XLOOKUP(C5,'Maths1.DailyAttendance'!$D$2:$D$16,'Maths1.DailyAttendance'!$R$2:$R$16,_xlfn.XLOOKUP(C5,'English Language'!$D$2:$D$16,'English Language'!$R$2:$R$16))) -> 0.8 | F5: =IF(D5=$N$3,(_xlfn.XLOOKUP(C5,'Physics1.DailyAttendance'!$D$2:$D$16,'Physics1.DailyAttendance'!$S$2:$S$16)),_xlfn.XLOOKUP(C5,'Maths1.DailyAttendance'!$D$2:$D$16,'Maths1.DailyAttendance'!$S$2:$S$16,_xlfn.XLOOKUP(C5,'English Language'!D$2:$D$16,'English Language'!$S$2:$S$16))) -> 88 | G5: =IF(D5=$N$3,(_xlfn.XLOOKUP(C5,'Physics1.DailyAttendance'!$D$2:$D$16,'Physics1.DailyAttendance'!$T$2:$T$16)),_xlfn.XLOOKUP(C5,'Maths1.DailyAttendance'!$D$2:$D$16,'Maths1.DailyAttendance'!$T$2:$T$16,_xlfn.XLOOKUP(C5,'English Language'!$D$2:$D$16,'English Language'!$T$2:$T$16))) -> 75 | H5: =IF(D5=$N$3,(_xlfn.XLOOKUP(C5,'Physics1.DailyAttendance'!$D$2:$D$16,'Physics1.DailyAttendance'!$U$2:$U$16)),_xlfn.XLOOKUP(C5,'Maths1.DailyAttendance'!$D$2:$D$16,'Maths1.DailyAttendance'!$U$2:$U$16,_xlfn.XLOOKUP(C5,'English Language'!$D$2:F$16,'English Language'!$U$2:$U$16))) -> Yes | I5: =(E5*40)+F5*0.15+G5*0.2+(IF(H5="Yes",25,0)) -> 85.2 | J5: =IF(I5>87,"Excellent",IF(I5<70,"Failed",IF(I5>77,"Good","Pass"))) -> Good | N5: English Language | Q5: Test1 | X5: 15
A6: =StudendEnroll!A6 -> Robert | B6: =StudendEnroll!B6 -> Hus | C6: =StudendEnroll!C6 -> Robertus@gmail.com | D6: =StudendEnroll!D6 -> Maths1 | E6: =IF(D6=$N$3,(_xlfn.XLOOKUP(C6,'Physics1.DailyAttendance'!$D$2:$D$14,'Physics1.DailyAttendance'!$R$2:$R$14)),_xlfn.XLOOKUP(C6,'Maths1.DailyAttendance'!$D$2:$D$16,'Maths1.DailyAttendance'!$R$2:$R$16,_xlfn.XLOOKUP(C6,'English Language'!$D$2:$D$16,'English Language'!$R$2:$R$16))) -> 1 | F6: =IF(D6=$N$3,(_xlfn.XLOOKUP(C6,'Physics1.DailyAttendance'!$D$2:$D$16,'Physics1.DailyAttendance'!$S$2:$S$16)),_xlfn.XLOOKUP(C6,'Maths1.DailyAttendance'!$D$2:$D$16,'Maths1.DailyAttendance'!$S$2:$S$16,_xlfn.XLOOKUP(C6,'English Language'!D$2:$D$16,'English Language'!$S$2:$S$16))) -> 81 | G6: =IF(D6=$N$3,(_xlfn.XLOOKUP(C6,'Physics1.DailyAttendance'!$D$2:$D$16,'Physics1.DailyAttendance'!$T$2:$T$16)),_xlfn.XLOOKUP(C6,'Maths1.DailyAttendance'!$D$2:$D$16,'Maths1.DailyAttendance'!$T$2:$T$16,_xlfn.XLOOKUP(C6,'English Language'!$D$2:$D$16,'English Language'!$T$2:$T$16))) -> 99 | H6: =IF(D6=$N$3,(_xlfn.XLOOKUP(C6,'Physics1.DailyAttendance'!$D$2:$D$16,'Physics1.DailyAttendance'!$U$2:$U$16)),_xlfn.XLOOKUP(C6,'Maths1.DailyAttendance'!$D$2:$D$16,'Maths1.DailyAttendance'!$U$2:$U$16,_xlfn.XLOOKUP(C6,'English Language'!$D$2:F$16,'English Language'!$U$2:$U$16))) -> Yes | I6: =(E6*40)+F6*0.15+G6*0.2+(IF(H6="Yes",25,0)) -> 96.95 | J6: =IF(I6>87,"Excellent",IF(I6<70,"Failed",IF(I6>77,"Good","Pass"))) -> Excellent | Q6: Test2 | X6: 20
A7: =StudendEnroll!A7 -> Omar | B7: =StudendEnroll!B7 -> Kasim | C7: =StudendEnroll!C7 -> Omaras@gmail.com | D7: =StudendEnroll!D7 -> Maths1 | E7: =IF(D7=$N$3,(_xlfn.XLOOKUP(C7,'Physics1.DailyAttendance'!$D$2:$D$14,'Physics1.DailyAttendance'!$R$2:$R$14)),_xlfn.XLOOKUP(C7,'Maths1.DailyAttendance'!$D$2:$D$16,'Maths1.DailyAttendance'!$R$2:$R$16,_xlfn.XLOOKUP(C7,'English Language'!$D$2:$D$16,'English Language'!$R$2:$R$16))) -> 0.6 | F7: =IF(D7=$N$3,(_xlfn.XLOOKUP(C7,'Physics1.DailyAttendance'!$D$2:$D$16,'Physics1.DailyAttendance'!$S$2:$S$16)),_xlfn.XLOOKUP(C7,'Maths1.DailyAttendance'!$D$2:$D$16,'Maths1.DailyAttendance'!$S$2:$S$16,_xlfn.XLOOKUP(C7,'English Language'!D$2:$D$16,'English Language'!$S$2:$S$16))) -> 77 | G7: =IF(D7=$N$3,(_xlfn.XLOOKUP(C7,'Physics1.DailyAttendance'!$D$2:$D$16,'Physics1.DailyAttendance'!$T$2:$T$16)),_xlfn.XLOOKUP(C7,'Maths1.DailyAttendance'!$D$2:$D$16,'Maths1.DailyAttendance'!$T$2:$T$16,_xlfn.XLOOKUP(C7,'English Language'!$D$2:$D$16,'English Language'!$T$2:$T$16))) -> 67 | H7: =IF(D7=$N$3,(_xlfn.XLOOKUP(C7,'Physics1.DailyAttendance'!$D$2:$D$16,'Physics1.DailyAttendance'!$U$2:$U$16)),_xlfn.XLOOKUP(C7,'Maths1.DailyAttendance'!$D$2:$D$16,'Maths1.DailyAttendance'!$U$2:$U$16,_xlfn.XLOOKUP(C7,'English Language'!$D$2:F$16,'English Language'!$U$2:$U$16))) -> Yes | I7: =(E7*40)+F7*0.15+G7*0.2+(IF(H7="Yes",25,0)) -> 73.95 | J7: =IF(I7>87,"Excellent",IF(I7<70,"Failed",IF(I7>77,"Good","Pass"))) -> Pass | Q7: Final assignment | X7: 25
A8: =StudendEnroll!A8 -> Diana | B8: =StudendEnroll!B8 -> Pinto | C8: =StudendEnroll!C8 -> Dianain@gmail.com | D8: =StudendEnroll!D8 -> Physics1 | E8: =IF(D8=$N$3,(_xlfn.XLOOKUP(C8,'Physics1.DailyAttendance'!$D$2:$D$14,'Physics1.DailyAttendance'!$R$2:$R$14)),_xlfn.XLOOKUP(C8,'Maths1.DailyAttendance'!$D$2:$D$16,'Maths1.DailyAttendance'!$R$2:$R$16,_xlfn.XLOOKUP(C8,'English Language'!$D$2:$D$16,'English Language'!$R$2:$R$16))) -> 0.4 | F8: =IF(D8=$N$3,(_xlfn.XLOOKUP(C8,'Physics1.DailyAttendance'!$D$2:$D$16,'Physics1.DailyAttendance'!$S$2:$S$16)),_xlfn.XLOOKUP(C8,'Maths1.DailyAttendance'!$D$2:$D$16,'Maths1.DailyAttendance'!$S$2:$S$16,_xlfn.XLOOKUP(C8,'English Language'!D$2:$D$16,'English Language'!$S$2:$S$16))) -> 69 | G8: =IF(D8=$N$3,(_xlfn.XLOOKUP(C8,'Physics1.DailyAttendance'!$D$2:$D$16,'Physics1.DailyAttendance'!$T$2:$T$16)),_xlfn.XLOOKUP(C8,'Maths1.DailyAttendance'!$D$2:$D$16,'Maths1.DailyAttendance'!$T$2:$T$16,_xlfn.XLOOKUP(C8,'English Language'!$D$2:$D$16,'English Language'!$T$2:$T$16))) -> 33 | H8: =IF(D8=$N$3,(_xlfn.XLOOKUP(C8,'Physics1.DailyAttendance'!$D$2:$D$16,'Physics1.DailyAttendance'!$U$2:$U$16)),_xlfn.XLOOKUP(C8,'Maths1.DailyAttendance'!$D$2:$D$16,'Maths1.DailyAttendance'!$U$2:$U$16,_xlfn.XLOOKUP(C8,'English Language'!$D$2:F$16,'English Language'!$U$2:$U$16))) -> Yes | I8: =(E8*40)+F8*0.15+G8*0.2+(IF(H8="Yes",25,0)) -> 57.95 | J8: =IF(I8>87,"Excellent",IF(I8<70,"Failed",IF(I8>77,"Good","Pass"))) -> Failed | Q8: Overall | X8: 100
A9: =StudendEnroll!A9 -> Denis | B9: =StudendEnroll!B9 -> Rodman | C9: =StudendEnroll!C9 -> Denisod@gmail.com | D9: =StudendEnroll!D9 -> Maths1 | E9: =IF(D9=$N$3,(_xlfn.XLOOKUP(C9,'Physics1.DailyAttendance'!$D$2:$D$14,'Physics1.DailyAttendance'!$R$2:$R$14)),_xlfn.XLOOKUP(C9,'Maths1.DailyAttendance'!$D$2:$D$16,'Maths1.DailyAttendance'!$R$2:$R$16,_xlfn.XLOOKUP(C9,'English Language'!$D$2:$D$16,'English Language'!$R$2:$R$16))) -> 0.7 | F9: =IF(D9=$N$3,(_xlfn.XLOOKUP(C9,'Physics1.DailyAttendance'!$D$2:$D$16,'Physics1.DailyAttendance'!$S$2:$S$16)),_xlfn.XLOOKUP(C9,'Maths1.DailyAttendance'!$D$2:$D$16,'Maths1.DailyAttendance'!$S$2:$S$16,_xlfn.XLOOKUP(C9,'English Language'!D$2:$D$16,'English Language'!$S$2:$S$16))) -> 80 | G9: =IF(D9=$N$3,(_xlfn.XLOOKUP(C9,'Physics1.DailyAttendance'!$D$2:$D$16,'Physics1.DailyAttendance'!$T$2:$T$16)),_xlfn.XLOOKUP(C9,'Maths1.DailyAttendance'!$D$2:$D$16,'Maths1.DailyAttendance'!$T$2:$T$16,_xlfn.XLOOKUP(C9,'English Language'!$D$2:$D$16,'English Language'!$T$2:$T$16))) -> 78 | H9: =IF(D9=$N$3,(_xlfn.XLOOKUP(C9,'Physics1.DailyAttendance'!$D$2:$D$16,'Physics1.DailyAttendance'!$U$2:$U$16)),_xlfn.XLOOKUP(C9,'Maths1.DailyAttendance'!$D$2:$D$16,'Maths1.DailyAttendance'!$U$2:$U$16,_xlfn.XLOOKUP(C9,'English Language'!$D$2:F$16,'English Language'!$U$2:$U$16))) -> Yes | I9: =(E9*40)+F9*0.15+G9*0.2+(IF(H9="Yes",25,0)) -> 80.6 | J9: =IF(I9>87,"Excellent",IF(I9<70,"Failed",IF(I9>77,"Good","Pass"))) -> Good | Q9: Score to pass | X9: >=70
A10: =StudendEnroll!A10 -> Kate | B10: =StudendEnroll!B10 -> Potter | C10: =StudendEnroll!C10 -> Kateot@gmail.com | D10: =StudendEnroll!D10 -> Physics1 | E10: =IF(D10=$N$3,(_xlfn.XLOOKUP(C10,'Physics1.DailyAttendance'!$D$2:$D$14,'Physics1.DailyAttendance'!$R$2:$R$14)),_xlfn.XLOOKUP(C10,'Maths1.DailyAttendance'!$D$2:$D$16,'Maths1.DailyAttendance'!$R$2:$R$16,_xlfn.XLOOKUP(C10,'English Language'!$D$2:$D$16,'English Language'!$R$2:$R$16))) -> 1 | F10: =IF(D10=$N$3,(_xlfn.XLOOKUP(C10,'Physics1.DailyAttendance'!$D$2:$D$16,'Physics1.DailyAttendance'!$S$2:$S$16)),_xlfn.XLOOKUP(C10,'Maths1.DailyAttendance'!$D$2:$D$16,'Maths1.DailyAttendance'!$S$2:$S$16,_xlfn.XLOOKUP(C10,'English Language'!D$2:$D$16,'English Language'!$S$2:$S$16))) -> 100 | G10: =IF(D10=$N$3,(_xlfn.XLOOKUP(C10,'Physics1.DailyAttendance'!$D$2:$D$16,'Physics1.DailyAttendance'!$T$2:$T$16)),_xlfn.XLOOKUP(C10,'Maths1.DailyAttendance'!$D$2:$D$16,'Maths1.DailyAttendance'!$T$2:$T$16,_xlfn.XLOOKUP(C10,'English Language'!$D$2:$D$16,'English Language'!$T$2:$T$16))) -> 84 | H10: =IF(D10=$N$3,(_xlfn.XLOOKUP(C10,'Physics1.DailyAttendance'!$D$2:$D$16,'Physics1.DailyAttendance'!$U$2:$U$16)),_xlfn.XLOOKUP(C10,'Maths1.DailyAttendance'!$D$2:$D$16,'Maths1.DailyAttendance'!$U$2:$U$16,_xlfn.XLOOKUP(C10,'English Language'!$D$2:F$16,'English Language'!$U$2:$U$16))) -> Yes | I10: =(E10*40)+F10*0.15+G10*0.2+(IF(H10="Yes",25,0)) -> 96.8 | J10: =IF(I10>87,"Excellent",IF(I10<70,"Failed",IF(I10>77,"Good","Pass"))) -> Excellent | Q10: Score Good | X10: >77<87
A11: =StudendEnroll!A11 -> Manny | B11: =StudendEnroll!B11 -> Pac | C11: =StudendEnroll!C11 -> Mannyac@gmail.com | D11: =StudendEnroll!D11 -> Physics1 | E11: =IF(D11=$N$3,(_xlfn.XLOOKUP(C11,'Physics1.DailyAttendance'!$D$2:$D$14,'Physics1.DailyAttendance'!$R$2:$R$14)),_xlfn.XLOOKUP(C11,'Maths1.DailyAttendance'!$D$2:$D$16,'Maths1.DailyAttendance'!$R$2:$R$16,_xlfn.XLOOKUP(C11,'English Language'!$D$2:$D$16,'English Language'!$R$2:$R$16))) -> 0.6 | F11: =IF(D11=$N$3,(_xlfn.XLOOKUP(C11,'Physics1.DailyAttendance'!$D$2:$D$16,'Physics1.DailyAttendance'!$S$2:$S$16)),_xlfn.XLOOKUP(C11,'Maths1.DailyAttendance'!$D$2:$D$16,'Maths1.DailyAttendance'!$S$2:$S$16,_xlfn.XLOOKUP(C11,'English Language'!D$2:$D$16,'English Language'!$S$2:$S$16))) -> 70 | G11: =IF(D11=$N$3,(_xlfn.XLOOKUP(C11,'Physics1.DailyAttendance'!$D$2:$D$16,'Physics1.DailyAttendance'!$T$2:$T$16)),_xlfn.XLOOKUP(C11,'Maths1.DailyAttendance'!$D$2:$D$16,'Maths1.DailyAttendance'!$T$2:$T$16,_xlfn.XLOOKUP(C11,'English Language'!$D$2:$D$16,'English Language'!$T$2:$T$16))) -> 79 | H11: =IF(D11=$N$3,(_xlfn.XLOOKUP(C11,'Physics1.DailyAttendance'!$D$2:$D$16,'Physics1.DailyAttendance'!$U$2:$U$16)),_xlfn.XLOOKUP(C11,'Maths1.DailyAttendance'!$D$2:$D$16,'Maths1.DailyAttendance'!$U$2:$U$16,_xlfn.XLOOKUP(C11,'English Language'!$D$2:F$16,'English Language'!$U$2:$U$16))) -> Yes | I11: =(E11*40)+F11*0.15+G11*0.2+(IF(H11="Yes",25,0)) -> 75.3 | J11: =IF(I11>87,"Excellent",IF(I11<70,"Failed",IF(I11>77,"Good","Pass"))) -> Pass | Q11: Score Excellent | X11: >87
A12: =StudendEnroll!A12 -> Katy | B12: =StudendEnroll!B12 -> Perri | C12: =StudendEnroll!C12 -> Katyer@gmail.com | D12: =StudendEnroll!D12 -> Physics1 | E12: =IF(D12=$N$3,(_xlfn.XLOOKUP(C12,'Physics1.DailyAttendance'!$D$2:$D$14,'Physics1.DailyAttendance'!$R$2:$R$14)),_xlfn.XLOOKUP(C12,'Maths1.DailyAttendance'!$D$2:$D$16,'Maths1.DailyAttendance'!$R$2:$R$16,_xlfn.XLOOKUP(C12,'English Language'!$D$2:$D$16,'English Language'!$R$2:$R$16))) -> 1 | F12: =IF(D12=$N$3,(_xlfn.XLOOKUP(C12,'Physics1.DailyAttendance'!$D$2:$D$16,'Physics1.DailyAttendance'!$S$2:$S$16)),_xlfn.XLOOKUP(C12,'Maths1.DailyAttendance'!$D$2:$D$16,'Maths1.DailyAttendance'!$S$2:$S$16,_xlfn.XLOOKUP(C12,'English Language'!D$2:$D$16,'English Language'!$S$2:$S$16))) -> 43 | G12: =IF(D12=$N$3,(_xlfn.XLOOKUP(C12,'Physics1.DailyAttendance'!$D$2:$D$16,'Physics1.DailyAttendance'!$T$2:$T$16)),_xlfn.XLOOKUP(C12,'Maths1.DailyAttendance'!$D$2:$D$16,'Maths1.DailyAttendance'!$T$2:$T$16,_xlfn.XLOOKUP(C12,'English Language'!$D$2:$D$16,'English Language'!$T$2:$T$16))) -> 100 | H12: =IF(D12=$N$3,(_xlfn.XLOOKUP(C12,'Physics1.DailyAttendance'!$D$2:$D$16,'Physics1.DailyAttendance'!$U$2:$U$16)),_xlfn.XLOOKUP(C12,'Maths1.DailyAttendance'!$D$2:$D$16,'Maths1.DailyAttendance'!$U$2:$U$16,_xlfn.XLOOKUP(C12,'English Language'!$D$2:F$16,'English Language'!$U$2:$U$16))) -> Yes | I12: =(E12*40)+F12*0.15+G12*0.2+(IF(H12="Yes",25,0)) -> 91.45 | J12: =IF(I12>87,"Excellent",IF(I12<70,"Failed",IF(I12>77,"Good","Pass"))) -> Excellent
A13: =StudendEnroll!A13 -> Antony | B13: =StudendEnroll!B13 -> Ward | C13: =StudendEnroll!C13 -> Antonyar@gmail.com | D13: =StudendEnroll!D13 -> Physics1 | E13: =IF(D13=$N$3,(_xlfn.XLOOKUP(C13,'Physics1.DailyAttendance'!$D$2:$D$14,'Physics1.DailyAttendance'!$R$2:$R$14)),_xlfn.XLOOKUP(C13,'Maths1.DailyAttendance'!$D$2:$D$16,'Maths1.DailyAttendance'!$R$2:$R$16,_xlfn.XLOOKUP(C13,'English Language'!$D$2:$D$16,'English Language'!$R$2:$R$16))) -> 0.8 | F13: =IF(D13=$N$3,(_xlfn.XLOOKUP(C13,'Physics1.DailyAttendance'!$D$2:$D$16,'Physics1.DailyAttendance'!$S$2:$S$16)),_xlfn.XLOOKUP(C13,'Maths1.DailyAttendance'!$D$2:$D$16,'Maths1.DailyAttendance'!$S$2:$S$16,_xlfn.XLOOKUP(C13,'English Language'!D$2:$D$16,'English Language'!$S$2:$S$16))) -> 82 | G13: =IF(D13=$N$3,(_xlfn.XLOOKUP(C13,'Physics1.DailyAttendance'!$D$2:$D$16,'Physics1.DailyAttendance'!$T$2:$T$16)),_xlfn.XLOOKUP(C13,'Maths1.DailyAttendance'!$D$2:$D$16,'Maths1.DailyAttendance'!$T$2:$T$16,_xlfn.XLOOKUP(C13,'English Language'!$D$2:$D$16,'English Language'!$T$2:$T$16))) -> 88 | H13: =IF(D13=$N$3,(_xlfn.XLOOKUP(C13,'Physics1.DailyAttendance'!$D$2:$D$16,'Physics1.DailyAttendance'!$U$2:$U$16)),_xlfn.XLOOKUP(C13,'Maths1.DailyAttendance'!$D$2:$D$16,'Maths1.DailyAttendance'!$U$2:$U$16,_xlfn.XLOOKUP(C13,'English Language'!$D$2:F$16,'English Language'!$U$2:$U$16))) -> Yes | I13: =(E13*40)+F13*0.15+G13*0.2+(IF(H13="Yes",25,0)) -> 86.9 | J13: =IF(I13>87,"Excellent",IF(I13<70,"Failed",IF(I13>77,"Good","Pass"))) -> Good
A14: =StudendEnroll!A14 -> Billy | B14: =StudendEnroll!B14 -> Sane | C14: =StudendEnroll!C14 -> Billyan@gmail.com | D14: =StudendEnroll!D14 -> Physics1 | E14: =IF(D14=$N$3,(_xlfn.XLOOKUP(C14,'Physics1.DailyAttendance'!$D$2:$D$14,'Physics1.DailyAttendance'!$R$2:$R$14)),_xlfn.XLOOKUP(C14,'Maths1.DailyAttendance'!$D$2:$D$16,'Maths1.DailyAttendance'!$R$2:$R$16,_xlfn.XLOOKUP(C14,'English Language'!$D$2:$D$16,'English Language'!$R$2:$R$16))) -> 0.6 | F14: =IF(D14=$N$3,(_xlfn.XLOOKUP(C14,'Physics1.DailyAttendance'!$D$2:$D$16,'Physics1.DailyAttendance'!$S$2:$S$16)),_xlfn.XLOOKUP(C14,'Maths1.DailyAttendance'!$D$2:$D$16,'Maths1.DailyAttendance'!$S$2:$S$16,_xlfn.XLOOKUP(C14,'English Language'!D$2:$D$16,'English Language'!$S$2:$S$16))) -> 75 | G14: =IF(D14=$N$3,(_xlfn.XLOOKUP(C14,'Physics1.DailyAttendance'!$D$2:$D$16,'Physics1.DailyAttendance'!$T$2:$T$16)),_xlfn.XLOOKUP(C14,'Maths1.DailyAttendance'!$D$2:$D$16,'Maths1.DailyAttendance'!$T$2:$T$16,_xlfn.XLOOKUP(C14,'English Language'!$D$2:$D$16,'English Language'!$T$2:$T$16))) -> 81 | H14: =IF(D14=$N$3,(_xlfn.XLOOKUP(C14,'Physics1.DailyAttendance'!$D$2:$D$16,'Physics1.DailyAttendance'!$U$2:$U$16)),_xlfn.XLOOKUP(C14,'Maths1.DailyAttendance'!$D$2:$D$16,'Maths1.DailyAttendance'!$U$2:$U$16,_xlfn.XLOOKUP(C14,'English Language'!$D$2:F$16,'English Language'!$U$2:$U$16))) -> Yes | I14: =(E14*40)+F14*0.15+G14*0.2+(IF(H14="Yes",25,0)) -> 76.45 | J14: =IF(I14>87,"Excellent",IF(I14<70,"Failed",IF(I14>77,"Good","Pass"))) -> Pass
A15: =StudendEnroll!A15 -> Ronald | B15: =StudendEnroll!B15 -> Connan | C15: =StudendEnroll!C15 -> Ronaldon@gmail.com | D15: =StudendEnroll!D15 -> Physics1 | E15: =IF(D15=$N$3,(_xlfn.XLOOKUP(C15,'Physics1.DailyAttendance'!$D$2:$D$14,'Physics1.DailyAttendance'!$R$2:$R$14)),_xlfn.XLOOKUP(C15,'Maths1.DailyAttendance'!$D$2:$D$16,'Maths1.DailyAttendance'!$R$2:$R$16,_xlfn.XLOOKUP(C15,'English Language'!$D$2:$D$16,'English Language'!$R$2:$R$16))) -> 0.7 | F15: =IF(D15=$N$3,(_xlfn.XLOOKUP(C15,'Physics1.DailyAttendance'!$D$2:$D$16,'Physics1.DailyAttendance'!$S$2:$S$16)),_xlfn.XLOOKUP(C15,'Maths1.DailyAttendance'!$D$2:$D$16,'Maths1.DailyAttendance'!$S$2:$S$16,_xlfn.XLOOKUP(C15,'English Language'!D$2:$D$16,'English Language'!$S$2:$S$16))) -> 92 | G15: =IF(D15=$N$3,(_xlfn.XLOOKUP(C15,'Physics1.DailyAttendance'!$D$2:$D$16,'Physics1.DailyAttendance'!$T$2:$T$16)),_xlfn.XLOOKUP(C15,'Maths1.DailyAttendance'!$D$2:$D$16,'Maths1.DailyAttendance'!$T$2:$T$16,_xlfn.XLOOKUP(C15,'English Language'!$D$2:$D$16,'English Language'!$T$2:$T$16))) -> 79 | H15: =IF(D15=$N$3,(_xlfn.XLOOKUP(C15,'Physics1.DailyAttendance'!$D$2:$D$16,'Physics1.DailyAttendance'!$U$2:$U$16)),_xlfn.XLOOKUP(C15,'Maths1.DailyAttendance'!$D$2:$D$16,'Maths1.DailyAttendance'!$U$2:$U$16,_xlfn.XLOOKUP(C15,'English Language'!$D$2:F$16,'English Language'!$U$2:$U$16))) -> Yes | I15: =(E15*40)+F15*0.15+G15*0.2+(IF(H15="Yes",25,0)) -> 82.6 | J15: =IF(I15>87,"Excellent",IF(I15<70,"Failed",IF(I15>77,"Good","Pass"))) -> Good
A16: =StudendEnroll!A16 -> John | B16: =StudendEnroll!B16 -> Baderas | C16: =StudendEnroll!C16 -> Johnad@gmail.com | D16: =StudendEnroll!D16 -> Maths1 | E16: =IF(D16=$N$3,(_xlfn.XLOOKUP(C16,'Physics1.DailyAttendance'!$D$2:$D$14,'Physics1.DailyAttendance'!$R$2:$R$14)),_xlfn.XLOOKUP(C16,'Maths1.DailyAttendance'!$D$2:$D$16,'Maths1.DailyAttendance'!$R$2:$R$16,_xlfn.XLOOKUP(C16,'English Language'!$D$2:$D$16,'English Language'!$R$2:$R$16))) -> 0.9 | F16: =IF(D16=$N$3,(_xlfn.XLOOKUP(C16,'Physics1.DailyAttendance'!$D$2:$D$16,'Physics1.DailyAttendance'!$S$2:$S$16)),_xlfn.XLOOKUP(C16,'Maths1.DailyAttendance'!$D$2:$D$16,'Maths1.DailyAttendance'!$S$2:$S$16,_xlfn.XLOOKUP(C16,'English Language'!D$2:$D$16,'English Language'!$S$2:$S$16))) -> 60 | G16: =IF(D16=$N$3,(_xlfn.XLOOKUP(C16,'Physics1.DailyAttendance'!$D$2:$D$16,'Physics1.DailyAttendance'!$T$2:$T$16)),_xlfn.XLOOKUP(C16,'Maths1.DailyAttendance'!$D$2:$D$16,'Maths1.DailyAttendance'!$T$2:$T$16,_xlfn.XLOOKUP(C16,'English Language'!$D$2:$D$16,'English Language'!$T$2:$T$16))) -> 94 | H16: =IF(D16=$N$3,(_xlfn.XLOOKUP(C16,'Physics1.DailyAttendance'!$D$2:$D$16,'Physics1.DailyAttendance'!$U$2:$U$16)),_xlfn.XLOOKUP(C16,'Maths1.DailyAttendance'!$D$2:$D$16,'Maths1.DailyAttendance'!$U$2:$U$16,_xlfn.XLOOKUP(C16,'English Language'!$D$2:F$16,'English Language'!$U$2:$U$16))) -> Yes | I16: =(E16*40)+F16*0.15+G16*0.2+(IF(H16="Yes",25,0)) -> 88.8 | J16: =IF(I16>87,"Excellent",IF(I16<70,"Failed",IF(I16>77,"Good","Pass"))) -> Excellent
A17: =StudendEnroll!A17 -> Ronald | B17: =StudendEnroll!B17 -> Connan | C17: =StudendEnroll!C17 -> Ronaldon@gmail.com | D17: =StudendEnroll!D17 -> Maths1 | E17: =IF(D17=$N$3,(_xlfn.XLOOKUP(C17,'Physics1.DailyAttendance'!$D$2:$D$14,'Physics1.DailyAttendance'!$R$2:$R$14)),_xlfn.XLOOKUP(C17,'Maths1.DailyAttendance'!$D$2:$D$16,'Maths1.DailyAttendance'!$R$2:$R$16,_xlfn.XLOOKUP(C17,'English Language'!$D$2:$D$16,'English Language'!$R$2:$R$16))) -> 0.6 | F17: =IF(D17=$N$3,(_xlfn.XLOOKUP(C17,'Physics1.DailyAttendance'!$D$2:$D$16,'Physics1.DailyAttendance'!$S$2:$S$16)),_xlfn.XLOOKUP(C17,'Maths1.DailyAttendance'!$D$2:$D$16,'Maths1.DailyAttendance'!$S$2:$S$16,_xlfn.XLOOKUP(C17,'English Language'!D$2:$D$16,'English Language'!$S$2:$S$16))) -> 92 | G17: =IF(D17=$N$3,(_xlfn.XLOOKUP(C17,'Physics1.DailyAttendance'!$D$2:$D$16,'Physics1.DailyAttendance'!$T$2:$T$16)),_xlfn.XLOOKUP(C17,'Maths1.DailyAttendance'!$D$2:$D$16,'Maths1.DailyAttendance'!$T$2:$T$16,_xlfn.XLOOKUP(C17,'English Language'!$D$2:$D$16,'English Language'!$T$2:$T$16))) -> 79 | H17: =IF(D17=$N$3,(_xlfn.XLOOKUP(C17,'Physics1.DailyAttendance'!$D$2:$D$16,'Physics1.DailyAttendance'!$U$2:$U$16)),_xlfn.XLOOKUP(C17,'Maths1.DailyAttendance'!$D$2:$D$16,'Maths1.DailyAttendance'!$U$2:$U$16,_xlfn.XLOOKUP(C17,'English Language'!$D$2:F$16,'English Language'!$U$2:$U$16))) -> Yes | I17: =(E17*40)+F17*0.15+G17*0.2+(IF(H17="Yes",25,0)) -> 78.6 | J17: =IF(I17>87,"Excellent",IF(I17<70,"Failed",IF(I17>77,"Good","Pass"))) -> Good
A18: =StudendEnroll!A18 -> Dennis | B18: =StudendEnroll!B18 -> Menace | C18: =StudendEnroll!C18 -> Dennisen@gmail.com | D18: =StudendEnroll!D18 -> Maths1 | E18: =IF(D18=$N$3,(_xlfn.XLOOKUP(C18,'Physics1.DailyAttendance'!$D$2:$D$14,'Physics1.DailyAttendance'!$R$2:$R$14)),_xlfn.XLOOKUP(C18,'Maths1.DailyAttendance'!$D$2:$D$16,'Maths1.DailyAttendance'!$R$2:$R$16,_xlfn.XLOOKUP(C18,'English Language'!$D$2:$D$16,'English Language'!$R$2:$R$16))) -> 1 | F18: =IF(D18=$N$3,(_xlfn.XLOOKUP(C18,'Physics1.DailyAttendance'!$D$2:$D$16,'Physics1.DailyAttendance'!$S$2:$S$16)),_xlfn.XLOOKUP(C18,'Maths1.DailyAttendance'!$D$2:$D$16,'Maths1.DailyAttendance'!$S$2:$S$16,_xlfn.XLOOKUP(C18,'English Language'!D$2:$D$16,'English Language'!$S$2:$S$16))) -> 73 | G18: =IF(D18=$N$3,(_xlfn.XLOOKUP(C18,'Physics1.DailyAttendance'!$D$2:$D$16,'Physics1.DailyAttendance'!$T$2:$T$16)),_xlfn.XLOOKUP(C18,'Maths1.DailyAttendance'!$D$2:$D$16,'Maths1.DailyAttendance'!$T$2:$T$16,_xlfn.XLOOKUP(C18,'English Language'!$D$2:$D$16,'English Language'!$T$2:$T$16))) -> 99 | H18: =IF(D18=$N$3,(_xlfn.XLOOKUP(C18,'Physics1.DailyAttendance'!$D$2:$D$16,'Physics1.DailyAttendance'!$U$2:$U$16)),_xlfn.XLOOKUP(C18,'Maths1.DailyAttendance'!$D$2:$D$16,'Maths1.DailyAttendance'!$U$2:$U$16,_xlfn.XLOOKUP(C18,'English Language'!$D$2:F$16,'English Language'!$U$2:$U$16))) -> Yes | I18: =(E18*40)+F18*0.15+G18*0.2+(IF(H18="Yes",25,0)) -> 95.75 | J18: =IF(I18>87,"Excellent",IF(I18<70,"Failed",IF(I18>77,"Good","Pass"))) -> Excellent
A19: =StudendEnroll!A19 -> Ronald | B19: =StudendEnroll!B19 -> Pape | C19: =StudendEnroll!C19 -> Ronaldap@gmail.com | D19: =StudendEnroll!D19 -> Maths1 | E19: =IF(D19=$N$3,(_xlfn.XLOOKUP(C19,'Physics1.DailyAttendance'!$D$2:$D$14,'Physics1.DailyAttendance'!$R$2:$R$14)),_xlfn.XLOOKUP(C19,'Maths1.DailyAttendance'!$D$2:$D$16,'Maths1.DailyAttendance'!$R$2:$R$16,_xlfn.XLOOKUP(C19,'English Language'!$D$2:$D$16,'English Language'!$R$2:$R$16))) -> 0.7 | F19: =IF(D19=$N$3,(_xlfn.XLOOKUP(C19,'Physics1.DailyAttendance'!$D$2:$D$16,'Physics1.DailyAttendance'!$S$2:$S$16)),_xlfn.XLOOKUP(C19,'Maths1.DailyAttendance'!$D$2:$D$16,'Maths1.DailyAttendance'!$S$2:$S$16,_xlfn.XLOOKUP(C19,'English Language'!D$2:$D$16,'English Language'!$S$2:$S$16))) -> 73 | G19: =IF(D19=$N$3,(_xlfn.XLOOKUP(C19,'Physics1.DailyAttendance'!$D$2:$D$16,'Physics1.DailyAttendance'!$T$2:$T$16)),_xlfn.XLOOKUP(C19,'Maths1.DailyAttendance'!$D$2:$D$16,'Maths1.DailyAttendance'!$T$2:$T$16,_xlfn.XLOOKUP(C19,'English Language'!$D$2:$D$16,'English Language'!$T$2:$T$16))) -> 68 | H19: =IF(D19=$N$3,(_xlfn.XLOOKUP(C19,'Physics1.DailyAttendance'!$D$2:$D$16,'Physics1.DailyAttendance'!$U$2:$U$16)),_xlfn.XLOOKUP(C19,'Maths1.DailyAttendance'!$D$2:$D$16,'Maths1.DailyAttendance'!$U$2:$U$16,_xlfn.XLOOKUP(C19,'English Language'!$D$2:F$16,'English Language'!$U$2:$U$16))) -> Yes | I19: =(E19*40)+F19*0.15+G19*0.2+(IF(H19="Yes",25,0)) -> 77.55 | J19: =IF(I19>87,"Excellent",IF(I19<70,"Failed",IF(I19>77,"Good","Pass"))) -> Good
A20: =StudendEnroll!A20 -> Walid | B20: =StudendEnroll!B20 -> Matip | C20: =StudendEnroll!C20 -> Walidat@gmail.com | D20: =StudendEnroll!D20 -> Maths1 | E20: =IF(D20=$N$3,(_xlfn.XLOOKUP(C20,'Physics1.DailyAttendance'!$D$2:$D$14,'Physics1.DailyAttendance'!$R$2:$R$14)),_xlfn.XLOOKUP(C20,'Maths1.DailyAttendance'!$D$2:$D$16,'Maths1.DailyAttendance'!$R$2:$R$16,_xlfn.XLOOKUP(C20,'English Language'!$D$2:$D$16,'English Language'!$R$2:$R$16))) -> 0.9 | F20: =IF(D20=$N$3,(_xlfn.XLOOKUP(C20,'Physics1.DailyAttendance'!$D$2:$D$16,'Physics1.DailyAttendance'!$S$2:$S$16)),_xlfn.XLOOKUP(C20,'Maths1.DailyAttendance'!$D$2:$D$16,'Maths1.DailyAttendance'!$S$2:$S$16,_xlfn.XLOOKUP(C20,'English Language'!D$2:$D$16,'English Language'!$S$2:$S$16))) -> 88 | G20: =IF(D20=$N$3,(_xlfn.XLOOKUP(C20,'Physics1.DailyAttendance'!$D$2:$D$16,'Physics1.DailyAttendance'!$T$2:$T$16)),_xlfn.XLOOKUP(C20,'Maths1.DailyAttendance'!$D$2:$D$16,'Maths1.DailyAttendance'!$T$2:$T$16,_xlfn.XLOOKUP(C20,'English Language'!$D$2:$D$16,'English Language'!$T$2:$T$16))) -> 80 | H20: =IF(D20=$N$3,(_xlfn.XLOOKUP(C20,'Physics1.DailyAttendance'!$D$2:$D$16,'Physics1.DailyAttendance'!$U$2:$U$16)),_xlfn.XLOOKUP(C20,'Maths1.DailyAttendance'!$D$2:$D$16,'Maths1.DailyAttendance'!$U$2:$U$16,_xlfn.XLOOKUP(C20,'English Language'!$D$2:F$16,'English Language'!$U$2:$U$16))) -> Yes | I20: =(E20*40)+F20*0.15+G20*0.2+(IF(H20="Yes",25,0)) -> 90.2 | J20: =IF(I20>87,"Excellent",IF(I20<70,"Failed",IF(I20>77,"Good","Pass"))) -> Excellent
A21: =StudendEnroll!A21 -> Donna | B21: =StudendEnroll!B21 -> Corleone | C21: =StudendEnroll!C21 -> Donnaor@gmail.com | D21: =StudendEnroll!D21 -> Maths1 | E21: =IF(D21=$N$3,(_xlfn.XLOOKUP(C21,'Physics1.DailyAttendance'!$D$2:$D$14,'Physics1.DailyAttendance'!$R$2:$R$14)),_xlfn.XLOOKUP(C21,'Maths1.DailyAttendance'!$D$2:$D$16,'Maths1.DailyAttendance'!$R$2:$R$16,_xlfn.XLOOKUP(C21,'English Language'!$D$2:$D$16,'English Language'!$R$2:$R$16))) -> 0.9 | F21: =IF(D21=$N$3,(_xlfn.XLOOKUP(C21,'Physics1.DailyAttendance'!$D$2:$D$16,'Physics1.DailyAttendance'!$S$2:$S$16)),_xlfn.XLOOKUP(C21,'Maths1.DailyAttendance'!$D$2:$D$16,'Maths1.DailyAttendance'!$S$2:$S$16,_xlfn.XLOOKUP(C21,'English Language'!D$2:$D$16,'English Language'!$S$2:$S$16))) -> 96 | G21: =IF(D21=$N$3,(_xlfn.XLOOKUP(C21,'Physics1.DailyAttendance'!$D$2:$D$16,'Physics1.DailyAttendance'!$T$2:$T$16)),_xlfn.XLOOKUP(C21,'Maths1.DailyAttendance'!$D$2:$D$16,'Maths1.DailyAttendance'!$T$2:$T$16,_xlfn.XLOOKUP(C21,'English Language'!$D$2:$D$16,'English Language'!$T$2:$T$16))) -> 90 | H21: =IF(D21=$N$3,(_xlfn.XLOOKUP(C21,'Physics1.DailyAttendance'!$D$2:$D$16,'Physics1.DailyAttendance'!$U$2:$U$16)),_xlfn.XLOOKUP(C21,'Maths1.DailyAttendance'!$D$2:$D$16,'Maths1.DailyAttendance'!$U$2:$U$16,_xlfn.XLOOKUP(C21,'English Language'!$D$2:F$16,'English Language'!$U$2:$U$16))) -> Yes | I21: =(E21*40)+F21*0.15+G21*0.2+(IF(H21="Yes",25,0)) -> 93.4 | J21: =IF(I21>87,"Excellent",IF(I21<70,"Failed",IF(I21>77,"Good","Pass"))) -> Excellent
A22: =StudendEnroll!A22 -> Mary | B22: =StudendEnroll!B22 -> Connan | C22: =StudendEnroll!C22 -> Maryon@gmail.com | D22: =StudendEnroll!D22 -> Maths1 | E22: =IF(D22=$N$3,(_xlfn.XLOOKUP(C22,'Physics1.DailyAttendance'!$D$2:$D$14,'Physics1.DailyAttendance'!$R$2:$R$14)),_xlfn.XLOOKUP(C22,'Maths1.DailyAttendance'!$D$2:$D$16,'Maths1.DailyAttendance'!$R$2:$R$16,_xlfn.XLOOKUP(C22,'English Language'!$D$2:$D$16,'English Language'!$R$2:$R$16))) -> 0.6 | F22: =IF(D22=$N$3,(_xlfn.XLOOKUP(C22,'Physics1.DailyAttendance'!$D$2:$D$16,'Physics1.DailyAttendance'!$S$2:$S$16)),_xlfn.XLOOKUP(C22,'Maths1.DailyAttendance'!$D$2:$D$16,'Maths1.DailyAttendance'!$S$2:$S$16,_xlfn.XLOOKUP(C22,'English Language'!D$2:$D$16,'English Language'!$S$2:$S$16))) -> 60 | G22: =IF(D22=$N$3,(_xlfn.XLOOKUP(C22,'Physics1.DailyAttendance'!$D$2:$D$16,'Physics1.DailyAttendance'!$T$2:$T$16)),_xlfn.XLOOKUP(C22,'Maths1.DailyAttendance'!$D$2:$D$16,'Maths1.DailyAttendance'!$T$2:$T$16,_xlfn.XLOOKUP(C22,'English Language'!$D$2:$D$16,'English Language'!$T$2:$T$16))) -> 91 | H22: =IF(D22=$N$3,(_xlfn.XLOOKUP(C22,'Physics1.DailyAttendance'!$D$2:$D$16,'Physics1.DailyAttendance'!$U$2:$U$16)),_xlfn.XLOOKUP(C22,'Maths1.DailyAttendance'!$D$2:$D$16,'Maths1.DailyAttendance'!$U$2:$U$16,_xlfn.XLOOKUP(C22,'English Language'!$D$2:F$16,'English Language'!$U$2:$U$16))) -> Yes | I22: =(E22*40)+F22*0.15+G22*0.2+(IF(H22="Yes",25,0)) -> 76.2 | J22: =IF(I22>87,"Excellent",IF(I22<70,"Failed",IF(I22>77,"Good","Pass"))) -> Pass
A23: =StudendEnroll!A23 -> Dustin | B23: =StudendEnroll!B23 -> Boier | C23: =StudendEnroll!C23 -> Dustinoi@gmail.com | D23: =StudendEnroll!D23 -> Maths1 | E23: =IF(D23=$N$3,(_xlfn.XLOOKUP(C23,'Physics1.DailyAttendance'!$D$2:$D$14,'Physics1.DailyAttendance'!$R$2:$R$14)),_xlfn.XLOOKUP(C23,'Maths1.DailyAttendance'!$D$2:$D$16,'Maths1.DailyAttendance'!$R$2:$R$16,_xlfn.XLOOKUP(C23,'English Language'!$D$2:$D$16,'English Language'!$R$2:$R$16))) -> 0.2 | F23: =IF(D23=$N$3,(_xlfn.XLOOKUP(C23,'Physics1.DailyAttendance'!$D$2:$D$16,'Physics1.DailyAttendance'!$S$2:$S$16)),_xlfn.XLOOKUP(C23,'Maths1.DailyAttendance'!$D$2:$D$16,'Maths1.DailyAttendance'!$S$2:$S$16,_xlfn.XLOOKUP(C23,'English Language'!D$2:$D$16,'English Language'!$S$2:$S$16))) -> 0 | G23: =IF(D23=$N$3,(_xlfn.XLOOKUP(C23,'Physics1.DailyAttendance'!$D$2:$D$16,'Physics1.DailyAttendance'!$T$2:$T$16)),_xlfn.XLOOKUP(C23,'Maths1.DailyAttendance'!$D$2:$D$16,'Maths1.DailyAttendance'!$T$2:$T$16,_xlfn.XLOOKUP(C23,'English Language'!$D$2:$D$16,'English Language'!$T$2:$T$16))) -> 37 | H23: =IF(D23=$N$3,(_xlfn.XLOOKUP(C23,'Physics1.DailyAttendance'!$D$2:$D$16,'Physics1.DailyAttendance'!$U$2:$U$16)),_xlfn.XLOOKUP(C23,'Maths1.DailyAttendance'!$D$2:$D$16,'Maths1.DailyAttendance'!$U$2:$U$16,_xlfn.XLOOKUP(C23,'English Language'!$D$2:F$16,'English Language'!$U$2:$U$16))) -> No | I23: =(E23*40)+F23*0.15+G23*0.2+(IF(H23="Yes",25,0)) -> 15.4 | J23: =IF(I23>87,"Excellent",IF(I23<70,"Failed",IF(I23>77,"Good","Pass"))) -> Failed
... A27: =StudendEnroll!A27 -> Andres | B27: =StudendEnroll!B27 -> Iniesti | C27: =StudendEnroll!C27 -> Andresni@gmail.com | D27: =StudendEnroll!D27 -> Maths1 | E27: =IF(D27=$N$3,(_xlfn.XLOOKUP(C27,'Physics1.DailyAttendance'!$D$2:$D$14,'Physics1.DailyAttendance'!$R$2:$R$14)),_xlfn.XLOOKUP(C27,'Maths1.DailyAttendance'!$D$2:$D$16,'Maths1.DailyAttendance'!$R$2:$R$16,_xlfn.XLOOKUP(C27,'English Language'!$D$2:$D$16,'English Language'!$R$2:$R$16))) -> 0.7 | F27: =IF(D27=$N$3,(_xlfn.XLOOKUP(C27,'Physics1.DailyAttendance'!$D$2:$D$16,'Physics1.DailyAttendance'!$S$2:$S$16)),_xlfn.XLOOKUP(C27,'Maths1.DailyAttendance'!$D$2:$D$16,'Maths1.DailyAttendance'!$S$2:$S$16,_xlfn.XLOOKUP(C27,'English Language'!D$2:$D$16,'English Language'!$S$2:$S$16))) -> 90 | G27: =IF(D27=$N$3,(_xlfn.XLOOKUP(C27,'Physics1.DailyAttendance'!$D$2:$D$16,'Physics1.DailyAttendance'!$T$2:$T$16)),_xlfn.XLOOKUP(C27,'Maths1.DailyAttendance'!$D$2:$D$16,'Maths1.DailyAttendance'!$T$2:$T$16,_xlfn.XLOOKUP(C27,'English Language'!$D$2:$D$16,'English Language'!$T$2:$T$16))) -> 87 | H27: =IF(D27=$N$3,(_xlfn.XLOOKUP(C27,'Physics1.DailyAttendance'!$D$2:$D$16,'Physics1.DailyAttendance'!$U$2:$U$16)),_xlfn.XLOOKUP(C27,'Maths1.DailyAttendance'!$D$2:$D$16,'Maths1.DailyAttendance'!$U$2:$U$16,_xlfn.XLOOKUP(C27,'English Language'!$D$2:F$16,'English Language'!$U$2:$U$16))) -> Yes | I27: =(E27*40)+F27*0.15+G27*0.2+(IF(H27="Yes",25,0)) -> 83.9 | J27: =IF(I27>87,"Excellent",IF(I27<70,"Failed",IF(I27>77,"Good","Pass"))) -> Good
A28: =StudendEnroll!A28 -> Katie | B28: =StudendEnroll!B28 -> Parn | C28: =StudendEnroll!C28 -> Katiear@gmail.com | D28: =StudendEnroll!D28 -> English Language | E28: =IF(D28=$N$3,(_xlfn.XLOOKUP(C28,'Physics1.DailyAttendance'!$D$2:$D$14,'Physics1.DailyAttendance'!$R$2:$R$14)),_xlfn.XLOOKUP(C28,'Maths1.DailyAttendance'!$D$2:$D$16,'Maths1.DailyAttendance'!$R$2:$R$16,_xlfn.XLOOKUP(C28,'English Language'!$D$2:$D$16,'English Language'!$R$2:$R$16))) -> 0.9 | F28: =IF(D28=$N$3,(_xlfn.XLOOKUP(C28,'Physics1.DailyAttendance'!$D$2:$D$16,'Physics1.DailyAttendance'!$S$2:$S$16)),_xlfn.XLOOKUP(C28,'Maths1.DailyAttendance'!$D$2:$D$16,'Maths1.DailyAttendance'!$S$2:$S$16,_xlfn.XLOOKUP(C28,'English Language'!D$2:$D$16,'English Language'!$S$2:$S$16))) -> 96 | G28: =IF(D28=$N$3,(_xlfn.XLOOKUP(C28,'Physics1.DailyAttendance'!$D$2:$D$16,'Physics1.DailyAttendance'!$T$2:$T$16)),_xlfn.XLOOKUP(C28,'Maths1.DailyAttendance'!$D$2:$D$16,'Maths1.DailyAttendance'!$T$2:$T$16,_xlfn.XLOOKUP(C28,'English Language'!$D$2:$D$16,'English Language'!$T$2:$T$16))) -> 88 | H28: =IF(D28=$N$3,(_xlfn.XLOOKUP(C28,'Physics1.DailyAttendance'!$D$2:$D$16,'Physics1.DailyAttendance'!$U$2:$U$16)),_xlfn.XLOOKUP(C28,'Maths1.DailyAttendance'!$D$2:$D$16,'Maths1.DailyAttendance'!$U$2:$U$16,_xlfn.XLOOKUP(C28,'English Language'!$D$2:D$16,'English Language'!$U$2:$U$16))) -> Yes | I28: =(E28*40)+F28*0.15+G28*0.2+(IF(H28="Yes",25,0)) -> 93 | J28: =IF(I28>87,"Excellent",IF(I28<70,"Failed",IF(I28>77,"Good","Pass"))) -> Excellent
A29: =StudendEnroll!A29 -> Ronaldo | B29: =StudendEnroll!B29 -> Felipe | C29: =StudendEnroll!C29 -> Ronaldoel@gmail.com | D29: =StudendEnroll!D29 -> English Language | E29: =IF(D29=$N$3,(_xlfn.XLOOKUP(C29,'Physics1.DailyAttendance'!$D$2:$D$14,'Physics1.DailyAttendance'!$R$2:$R$14)),_xlfn.XLOOKUP(C29,'Maths1.DailyAttendance'!$D$2:$D$16,'Maths1.DailyAttendance'!$R$2:$R$16,_xlfn.XLOOKUP(C29,'English Language'!$D$2:$D$16,'English Language'!$R$2:$R$16))) -> 0.8 | F29: =IF(D29=$N$3,(_xlfn.XLOOKUP(C29,'Physics1.DailyAttendance'!$D$2:$D$16,'Physics1.DailyAttendance'!$S$2:$S$16)),_xlfn.XLOOKUP(C29,'Maths1.DailyAttendance'!$D$2:$D$16,'Maths1.DailyAttendance'!$S$2:$S$16,_xlfn.XLOOKUP(C29,'English Language'!D$2:$D$16,'English Language'!$S$2:$S$16))) -> 55 | G29: =IF(D29=$N$3,(_xlfn.XLOOKUP(C29,'Physics1.DailyAttendance'!$D$2:$D$16,'Physics1.DailyAttendance'!$T$2:$T$16)),_xlfn.XLOOKUP(C29,'Maths1.DailyAttendance'!$D$2:$D$16,'Maths1.DailyAttendance'!$T$2:$T$16,_xlfn.XLOOKUP(C29,'English Language'!$D$2:$D$16,'English Language'!$T$2:$T$16))) -> 66 | H29: =IF(D29=$N$3,(_xlfn.XLOOKUP(C29,'Physics1.DailyAttendance'!$D$2:$D$16,'Physics1.DailyAttendance'!$U$2:$U$16)),_xlfn.XLOOKUP(C29,'Maths1.DailyAttendance'!$D$2:$D$16,'Maths1.DailyAttendance'!$U$2:$U$16,_xlfn.XLOOKUP(C29,'English Language'!$D$2:D$16,'English Language'!$U$2:$U$16))) -> No | I29: =(E29*40)+F29*0.15+G29*0.2+(IF(H29="Yes",25,0)) -> 53.45 | J29: =IF(I29>87,"Excellent",IF(I29<70,"Failed",IF(I29>77,"Good","Pass"))) -> Failed
A30: =StudendEnroll!A30 -> Dean | B30: =StudendEnroll!B30 -> Jolie | C30: =StudendEnroll!C30 -> Deanol@gmail.com | D30: =StudendEnroll!D30 -> English Language | E30: =IF(D30=$N$3,(_xlfn.XLOOKUP(C30,'Physics1.DailyAttendance'!$D$2:$D$14,'Physics1.DailyAttendance'!$R$2:$R$14)),_xlfn.XLOOKUP(C30,'Maths1.DailyAttendance'!$D$2:$D$16,'Maths1.DailyAttendance'!$R$2:$R$16,_xlfn.XLOOKUP(C30,'English Language'!$D$2:$D$16,'English Language'!$R$2:$R$16))) -> 1 | F30: =IF(D30=$N$3,(_xlfn.XLOOKUP(C30,'Physics1.DailyAttendance'!$D$2:$D$16,'Physics1.DailyAttendance'!$S$2:$S$16)),_xlfn.XLOOKUP(C30,'Maths1.DailyAttendance'!$D$2:$D$16,'Maths1.DailyAttendance'!$S$2:$S$16,_xlfn.XLOOKUP(C30,'English Language'!D$2:$D$16,'English Language'!$S$2:$S$16))) -> 81 | G30: =IF(D30=$N$3,(_xlfn.XLOOKUP(C30,'Physics1.DailyAttendance'!$D$2:$D$16,'Physics1.DailyAttendance'!$T$2:$T$16)),_xlfn.XLOOKUP(C30,'Maths1.DailyAttendance'!$D$2:$D$16,'Maths1.DailyAttendance'!$T$2:$T$16,_xlfn.XLOOKUP(C30,'English Language'!$D$2:$D$16,'English Language'!$T$2:$T$16))) -> 99 | H30: =IF(D30=$N$3,(_xlfn.XLOOKUP(C30,'Physics1.DailyAttendance'!$D$2:$D$16,'Physics1.DailyAttendance'!$U$2:$U$16)),_xlfn.XLOOKUP(C30,'Maths1.DailyAttendance'!$D$2:$D$16,'Maths1.DailyAttendance'!$U$2:$U$16,_xlfn.XLOOKUP(C30,'English Language'!$D$2:D$16,'English Language'!$U$2:$U$16))) -> Yes | I30: =(E30*40)+F30*0.15+G30*0.2+(IF(H30="Yes",25,0)) -> 96.95 | J30: =IF(I30>87,"Excellent",IF(I30<70,"Failed",IF(I30>77,"Good","Pass"))) -> Excellent
A31: =StudendEnroll!A31 -> Paolo | B31: =StudendEnroll!B31 -> Jasmini | C31: =StudendEnroll!C31 -> Paoloas@gmail.com | D31: =StudendEnroll!D31 -> English Language | E31: =IF(D31=$N$3,(_xlfn.XLOOKUP(C31,'Physics1.DailyAttendance'!$D$2:$D$14,'Physics1.DailyAttendance'!$R$2:$R$14)),_xlfn.XLOOKUP(C31,'Maths1.DailyAttendance'!$D$2:$D$16,'Maths1.DailyAttendance'!$R$2:$R$16,_xlfn.XLOOKUP(C31,'English Language'!$D$2:$D$16,'English Language'!$R$2:$R$16))) -> 0.8 | F31: =IF(D31=$N$3,(_xlfn.XLOOKUP(C31,'Physics1.DailyAttendance'!$D$2:$D$16,'Physics1.DailyAttendance'!$S$2:$S$16)),_xlfn.XLOOKUP(C31,'Maths1.DailyAttendance'!$D$2:$D$16,'Maths1.DailyAttendance'!$S$2:$S$16,_xlfn.XLOOKUP(C31,'English Language'!D$2:$D$16,'English Language'!$S$2:$S$16))) -> 77 | G31: =IF(D31=$N$3,(_xlfn.XLOOKUP(C31,'Physics1.DailyAttendance'!$D$2:$D$16,'Physics1.DailyAttendance'!$T$2:$T$16)),_xlfn.XLOOKUP(C31,'Maths1.DailyAttendance'!$D$2:$D$16,'Maths1.DailyAttendance'!$T$2:$T$16,_xlfn.XLOOKUP(C31,'English Language'!$D$2:$D$16,'English Language'!$T$2:$T$16))) -> 87 | H31: =IF(D31=$N$3,(_xlfn.XLOOKUP(C31,'Physics1.DailyAttendance'!$D$2:$D$16,'Physics1.DailyAttendance'!$U$2:$U$16)),_xlfn.XLOOKUP(C31,'Maths1.DailyAttendance'!$D$2:$D$16,'Maths1.DailyAttendance'!$U$2:$U$16,_xlfn.XLOOKUP(C31,'English Language'!$D$2:D$16,'English Language'!$U$2:$U$16))) -> Yes | I31: =(E31*40)+F31*0.15+G31*0.2+(IF(H31="Yes",25,0)) -> 85.95 | J31: =IF(I31>87,"Excellent",IF(I31<70,"Failed",IF(I31>77,"Good","Pass"))) -> Good
A32: =StudendEnroll!A32 -> Jean | B32: =StudendEnroll!B32 -> Damme | C32: =StudendEnroll!C32 -> Jean am@gmail.com | D32: =StudendEnroll!D32 -> English Language | E32: =IF(D32=$N$3,(_xlfn.XLOOKUP(C32,'Physics1.DailyAttendance'!$D$2:$D$14,'Physics1.DailyAttendance'!$R$2:$R$14)),_xlfn.XLOOKUP(C32,'Maths1.DailyAttendance'!$D$2:$D$16,'Maths1.DailyAttendance'!$R$2:$R$16,_xlfn.XLOOKUP(C32,'English Language'!$D$2:$D$16,'English Language'!$R$2:$R$16))) -> 0.7 | F32: =IF(D32=$N$3,(_xlfn.XLOOKUP(C32,'Physics1.DailyAttendance'!$D$2:$D$16,'Physics1.DailyAttendance'!$S$2:$S$16)),_xlfn.XLOOKUP(C32,'Maths1.DailyAttendance'!$D$2:$D$16,'Maths1.DailyAttendance'!$S$2:$S$16,_xlfn.XLOOKUP(C32,'English Language'!D$2:$D$16,'English Language'!$S$2:$S$16))) -> 80 | G32: =IF(D32=$N$3,(_xlfn.XLOOKUP(C32,'Physics1.DailyAttendance'!$D$2:$D$16,'Physics1.DailyAttendance'!$T$2:$T$16)),_xlfn.XLOOKUP(C32,'Maths1.DailyAttendance'!$D$2:$D$16,'Maths1.DailyAttendance'!$T$2:$T$16,_xlfn.XLOOKUP(C32,'English Language'!$D$2:$D$16,'English Language'!$T$2:$T$16))) -> 78 | H32: =IF(D32=$N$3,(_xlfn.XLOOKUP(C32,'Physics1.DailyAttendance'!$D$2:$D$16,'Physics1.DailyAttendance'!$U$2:$U$16)),_xlfn.XLOOKUP(C32,'Maths1.DailyAttendance'!$D$2:$D$16,'Maths1.DailyAttendance'!$U$2:$U$16,_xlfn.XLOOKUP(C32,'English Language'!$D$2:D$16,'English Language'!$U$2:$U$16))) -> Yes | I32: =(E32*40)+F32*0.15+G32*0.2+(IF(H32="Yes",25,0)) -> 80.6 | J32: =IF(I32>87,"Excellent",IF(I32<70,"Failed",IF(I32>77,"Good","Pass"))) -> Good
A33: =StudendEnroll!A33 -> Helen | B33: =StudendEnroll!B33 -> Birren | C33: =StudendEnroll!C33 -> Helen ir@gmail.com | D33: =StudendEnroll!D33 -> English Language | E33: =IF(D33=$N$3,(_xlfn.XLOOKUP(C33,'Physics1.DailyAttendance'!$D$2:$D$14,'Physics1.DailyAttendance'!$R$2:$R$14)),_xlfn.XLOOKUP(C33,'Maths1.DailyAttendance'!$D$2:$D$16,'Maths1.DailyAttendance'!$R$2:$R$16,_xlfn.XLOOKUP(C33,'English Language'!$D$2:$D$16,'English Language'!$R$2:$R$16))) -> 0.9 | F33: =IF(D33=$N$3,(_xlfn.XLOOKUP(C33,'Physics1.DailyAttendance'!$D$2:$D$16,'Physics1.DailyAttendance'!$S$2:$S$16)),_xlfn.XLOOKUP(C33,'Maths1.DailyAttendance'!$D$2:$D$16,'Maths1.DailyAttendance'!$S$2:$S$16,_xlfn.XLOOKUP(C33,'English Language'!D$2:$D$16,'English Language'!$S$2:$S$16))) -> 60 | G33: =IF(D33=$N$3,(_xlfn.XLOOKUP(C33,'Physics1.DailyAttendance'!$D$2:$D$16,'Physics1.DailyAttendance'!$T$2:$T$16)),_xlfn.XLOOKUP(C33,'Maths1.DailyAttendance'!$D$2:$D$16,'Maths1.DailyAttendance'!$T$2:$T$16,_xlfn.XLOOKUP(C33,'English Language'!$D$2:$D$16,'English Language'!$T$2:$T$16))) -> 94 | H33: =IF(D33=$N$3,(_xlfn.XLOOKUP(C33,'Physics1.DailyAttendance'!$D$2:$D$16,'Physics1.DailyAttendance'!$U$2:$U$16)),_xlfn.XLOOKUP(C33,'Maths1.DailyAttendance'!$D$2:$D$16,'Maths1.DailyAttendance'!$U$2:$U$16,_xlfn.XLOOKUP(C33,'English Language'!$D$2:D$16,'English Language'!$U$2:$U$16))) -> Yes | I33: =(E33*40)+F33*0.15+G33*0.2+(IF(H33="Yes",25,0)) -> 88.8 | J33: =IF(I33>87,"Excellent",IF(I33<70,"Failed",IF(I33>77,"Good","Pass"))) -> Excellent
A34: =StudendEnroll!A34 -> Olivia | B34: =StudendEnroll!B34 -> Cander | C34: =StudendEnroll!C34 -> Oliviaan@gmail.com | D34: =StudendEnroll!D34 -> English Language | E34: =IF(D34=$N$3,(_xlfn.XLOOKUP(C34,'Physics1.DailyAttendance'!$D$2:$D$14,'Physics1.DailyAttendance'!$R$2:$R$14)),_xlfn.XLOOKUP(C34,'Maths1.DailyAttendance'!$D$2:$D$16,'Maths1.DailyAttendance'!$R$2:$R$16,_xlfn.XLOOKUP(C34,'English Language'!$D$2:$D$16,'English Language'!$R$2:$R$16))) -> 0.8 | F34: =IF(D34=$N$3,(_xlfn.XLOOKUP(C34,'Physics1.DailyAttendance'!$D$2:$D$16,'Physics1.DailyAttendance'!$S$2:$S$16)),_xlfn.XLOOKUP(C34,'Maths1.DailyAttendance'!$D$2:$D$16,'Maths1.DailyAttendance'!$S$2:$S$16,_xlfn.XLOOKUP(C34,'English Language'!D$2:$D$16,'English Language'!$S$2:$S$16))) -> 92 | G34: =IF(D34=$N$3,(_xlfn.XLOOKUP(C34,'Physics1.DailyAttendance'!$D$2:$D$16,'Physics1.DailyAttendance'!$T$2:$T$16)),_xlfn.XLOOKUP(C34,'Maths1.DailyAttendance'!$D$2:$D$16,'Maths1.DailyAttendance'!$T$2:$T$16,_xlfn.XLOOKUP(C34,'English Language'!$D$2:$D$16,'English Language'!$T$2:$T$16))) -> 79 | H34: =IF(D34=$N$3,(_xlfn.XLOOKUP(C34,'Physics1.DailyAttendance'!$D$2:$D$16,'Physics1.DailyAttendance'!$U$2:$U$16)),_xlfn.XLOOKUP(C34,'Maths1.DailyAttendance'!$D$2:$D$16,'Maths1.DailyAttendance'!$U$2:$U$16,_xlfn.XLOOKUP(C34,'English Language'!$D$2:D$16,'English Language'!$U$2:$U$16))) -> Yes | I34: =(E34*40)+F34*0.15+G34*0.2+(IF(H34="Yes",25,0)) -> 86.6 | J34: =IF(I34>87,"Excellent",IF(I34<70,"Failed",IF(I34>77,"Good","Pass"))) -> Good
A35: =StudendEnroll!A35 -> Evita | B35: =StudendEnroll!B35 -> Saron | C35: =StudendEnroll!C35 -> Evita ar@gmail.com | D35: =StudendEnroll!D35 -> English Language | E35: =IF(D35=$N$3,(_xlfn.XLOOKUP(C35,'Physics1.DailyAttendance'!$D$2:$D$14,'Physics1.DailyAttendance'!$R$2:$R$14)),_xlfn.XLOOKUP(C35,'Maths1.DailyAttendance'!$D$2:$D$16,'Maths1.DailyAttendance'!$R$2:$R$16,_xlfn.XLOOKUP(C35,'English Language'!$D$2:$D$16,'English Language'!$R$2:$R$16))) -> 1 | F35: =IF(D35=$N$3,(_xlfn.XLOOKUP(C35,'Physics1.DailyAttendance'!$D$2:$D$16,'Physics1.DailyAttendance'!$S$2:$S$16)),_xlfn.XLOOKUP(C35,'Maths1.DailyAttendance'!$D$2:$D$16,'Maths1.DailyAttendance'!$S$2:$S$16,_xlfn.XLOOKUP(C35,'English Language'!D$2:$D$16,'English Language'!$S$2:$S$16))) -> 73 | G35: =IF(D35=$N$3,(_xlfn.XLOOKUP(C35,'Physics1.DailyAttendance'!$D$2:$D$16,'Physics1.DailyAttendance'!$T$2:$T$16)),_xlfn.XLOOKUP(C35,'Maths1.DailyAttendance'!$D$2:$D$16,'Maths1.DailyAttendance'!$T$2:$T$16,_xlfn.XLOOKUP(C35,'English Language'!$D$2:$D$16,'English Language'!$T$2:$T$16))) -> 99 | H35: =IF(D35=$N$3,(_xlfn.XLOOKUP(C35,'Physics1.DailyAttendance'!$D$2:$D$16,'Physics1.DailyAttendance'!$U$2:$U$16)),_xlfn.XLOOKUP(C35,'Maths1.DailyAttendance'!$D$2:$D$16,'Maths1.DailyAttendance'!$U$2:$U$16,_xlfn.XLOOKUP(C35,'English Language'!$D$2:D$16,'English Language'!$U$2:$U$16))) -> Yes | I35: =(E35*40)+F35*0.15+G35*0.2+(IF(H35="Yes",25,0)) -> 95.75 | J35: =IF(I35>87,"Excellent",IF(I35<70,"Failed",IF(I35>77,"Good","Pass"))) -> Excellent
A36: =StudendEnroll!A36 -> Muhammed | B36: =StudendEnroll!B36 -> Hasan | C36: =StudendEnroll!C36 -> Muhammed as@gmail.com | D36: =StudendEnroll!D36 -> English Language | E36: =IF(D36=$N$3,(_xlfn.XLOOKUP(C36,'Physics1.DailyAttendance'!$D$2:$D$14,'Physics1.DailyAttendance'!$R$2:$R$14)),_xlfn.XLOOKUP(C36,'Maths1.DailyAttendance'!$D$2:$D$16,'Maths1.DailyAttendance'!$R$2:$R$16,_xlfn.XLOOKUP(C36,'English Language'!$D$2:$D$16,'English Language'!$R$2:$R$16))) -> 0.8 | F36: =IF(D36=$N$3,(_xlfn.XLOOKUP(C36,'Physics1.DailyAttendance'!$D$2:$D$16,'Physics1.DailyAttendance'!$S$2:$S$16)),_xlfn.XLOOKUP(C36,'Maths1.DailyAttendance'!$D$2:$D$16,'Maths1.DailyAttendance'!$S$2:$S$16,_xlfn.XLOOKUP(C36,'English Language'!D$2:$D$16,'English Language'!$S$2:$S$16))) -> 73 | G36: =IF(D36=$N$3,(_xlfn.XLOOKUP(C36,'Physics1.DailyAttendance'!$D$2:$D$16,'Physics1.DailyAttendance'!$T$2:$T$16)),_xlfn.XLOOKUP(C36,'Maths1.DailyAttendance'!$D$2:$D$16,'Maths1.DailyAttendance'!$T$2:$T$16,_xlfn.XLOOKUP(C36,'English Language'!$D$2:$D$16,'English Language'!$T$2:$T$16))) -> 68 | H36: =IF(D36=$N$3,(_xlfn.XLOOKUP(C36,'Physics1.DailyAttendance'!$D$2:$D$16,'Physics1.DailyAttendance'!$U$2:$U$16)),_xlfn.XLOOKUP(C36,'Maths1.DailyAttendance'!$D$2:$D$16,'Maths1.DailyAttendance'!$U$2:$U$16,_xlfn.XLOOKUP(C36,'English Language'!$D$2:D$16,'English Language'!$U$2:$U$16))) -> Yes | I36: =(E36*40)+F36*0.15+G36*0.2+(IF(H36="Yes",25,0)) -> 81.55 | J36: =IF(I36>87,"Excellent",IF(I36<70,"Failed",IF(I36>77,"Good","Pass"))) -> Good
A37: =StudendEnroll!A37 -> Bill | B37: =StudendEnroll!B37 -> Kill | C37: =StudendEnroll!C37 -> Billil@gmail.com | D37: =StudendEnroll!D37 -> English Language | E37: =IF(D37=$N$3,(_xlfn.XLOOKUP(C37,'Physics1.DailyAttendance'!$D$2:$D$14,'Physics1.DailyAttendance'!$R$2:$R$14)),_xlfn.XLOOKUP(C37,'Maths1.DailyAttendance'!$D$2:$D$16,'Maths1.DailyAttendance'!$R$2:$R$16,_xlfn.XLOOKUP(C37,'English Language'!$D$2:$D$16,'English Language'!$R$2:$R$16))) -> 0.9 | F37: =IF(D37=$N$3,(_xlfn.XLOOKUP(C37,'Physics1.DailyAttendance'!$D$2:$D$16,'Physics1.DailyAttendance'!$S$2:$S$16)),_xlfn.XLOOKUP(C37,'Maths1.DailyAttendance'!$D$2:$D$16,'Maths1.DailyAttendance'!$S$2:$S$16,_xlfn.XLOOKUP(C37,'English Language'!D$2:$D$16,'English Language'!$S$2:$S$16))) -> 88 | G37: =IF(D37=$N$3,(_xlfn.XLOOKUP(C37,'Physics1.DailyAttendance'!$D$2:$D$16,'Physics1.DailyAttendance'!$T$2:$T$16)),_xlfn.XLOOKUP(C37,'Maths1.DailyAttendance'!$D$2:$D$16,'Maths1.DailyAttendance'!$T$2:$T$16,_xlfn.XLOOKUP(C37,'English Language'!$D$2:$D$16,'English Language'!$T$2:$T$16))) -> 80 | H37: =IF(D37=$N$3,(_xlfn.XLOOKUP(C37,'Physics1.DailyAttendance'!$D$2:$D$16,'Physics1.DailyAttendance'!$U$2:$U$16)),_xlfn.XLOOKUP(C37,'Maths1.DailyAttendance'!$D$2:$D$16,'Maths1.DailyAttendance'!$U$2:$U$16,_xlfn.XLOOKUP(C37,'English Language'!$D$2:D$16,'English Language'!$U$2:$U$16))) -> Yes | I37: =(E37*40)+F37*0.15+G37*0.2+(IF(H37="Yes",25,0)) -> 90.2 | J37: =IF(I37>87,"Excellent",IF(I37<70,"Failed",IF(I37>77,"Good","Pass"))) -> Excellent
A38: =StudendEnroll!A38 -> Bario | B38: =StudendEnroll!B38 -> Sarmiento | C38: =StudendEnroll!C38 -> Barioar@gmail.com | D38: =StudendEnroll!D38 -> English Language | E38: =IF(D38=$N$3,(_xlfn.XLOOKUP(C38,'Physics1.DailyAttendance'!$D$2:$D$14,'Physics1.DailyAttendance'!$R$2:$R$14)),_xlfn.XLOOKUP(C38,'Maths1.DailyAttendance'!$D$2:$D$16,'Maths1.DailyAttendance'!$R$2:$R$16,_xlfn.XLOOKUP(C38,'English Language'!$D$2:$D$16,'English Language'!$R$2:$R$16))) -> 0.9 | F38: =IF(D38=$N$3,(_xlfn.XLOOKUP(C38,'Physics1.DailyAttendance'!$D$2:$D$16,'Physics1.DailyAttendance'!$S$2:$S$16)),_xlfn.XLOOKUP(C38,'Maths1.DailyAttendance'!$D$2:$D$16,'Maths1.DailyAttendance'!$S$2:$S$16,_xlfn.XLOOKUP(C38,'English Language'!D$2:$D$16,'English Language'!$S$2:$S$16))) -> 96 | G38: =IF(D38=$N$3,(_xlfn.XLOOKUP(C38,'Physics1.DailyAttendance'!$D$2:$D$16,'Physics1.DailyAttendance'!$T$2:$T$16)),_xlfn.XLOOKUP(C38,'Maths1.DailyAttendance'!$D$2:$D$16,'Maths1.DailyAttendance'!$T$2:$T$16,_xlfn.XLOOKUP(C38,'English Language'!$D$2:$D$16,'English Language'!$T$2:$T$16))) -> 90 | H38: =IF(D38=$N$3,(_xlfn.XLOOKUP(C38,'Physics1.DailyAttendance'!$D$2:$D$16,'Physics1.DailyAttendance'!$U$2:$U$16)),_xlfn.XLOOKUP(C38,'Maths1.DailyAttendance'!$D$2:$D$16,'Maths1.DailyAttendance'!$U$2:$U$16,_xlfn.XLOOKUP(C38,'English Language'!$D$2:D$16,'English Language'!$U$2:$U$16))) -> Yes | I38: =(E38*40)+F38*0.15+G38*0.2+(IF(H38="Yes",25,0)) -> 93.4 | J38: =IF(I38>87,"Excellent",IF(I38<70,"Failed",IF(I38>77,"Good","Pass"))) -> Excellent
A39: =StudendEnroll!A39 -> Silvio | B39: =StudendEnroll!B39 -> Zerosconi | C39: =StudendEnroll!C39 -> Silvioer@gmail.com | D39: =StudendEnroll!D39 -> English Language | E39: =IF(D39=$N$3,(_xlfn.XLOOKUP(C39,'Physics1.DailyAttendance'!$D$2:$D$14,'Physics1.DailyAttendance'!$R$2:$R$14)),_xlfn.XLOOKUP(C39,'Maths1.DailyAttendance'!$D$2:$D$16,'Maths1.DailyAttendance'!$R$2:$R$16,_xlfn.XLOOKUP(C39,'English Language'!$D$2:$D$16,'English Language'!$R$2:$R$16))) -> 0.5 | F39: =IF(D39=$N$3,(_xlfn.XLOOKUP(C39,'Physics1.DailyAttendance'!$D$2:$D$16,'Physics1.DailyAttendance'!$S$2:$S$16)),_xlfn.XLOOKUP(C39,'Maths1.DailyAttendance'!$D$2:$D$16,'Maths1.DailyAttendance'!$S$2:$S$16,_xlfn.XLOOKUP(C39,'English Language'!D$2:$D$16,'English Language'!$S$2:$S$16))) -> 70 | G39: =IF(D39=$N$3,(_xlfn.XLOOKUP(C39,'Physics1.DailyAttendance'!$D$2:$D$16,'Physics1.DailyAttendance'!$T$2:$T$16)),_xlfn.XLOOKUP(C39,'Maths1.DailyAttendance'!$D$2:$D$16,'Maths1.DailyAttendance'!$T$2:$T$16,_xlfn.XLOOKUP(C39,'English Language'!$D$2:$D$16,'English Language'!$T$2:$T$16))) -> 0 | H39: =IF(D39=$N$3,(_xlfn.XLOOKUP(C39,'Physics1.DailyAttendance'!$D$2:$D$16,'Physics1.DailyAttendance'!$U$2:$U$16)),_xlfn.XLOOKUP(C39,'Maths1.DailyAttendance'!$D$2:$D$16,'Maths1.DailyAttendance'!$U$2:$U$16,_xlfn.XLOOKUP(C39,'English Language'!$D$2:D$16,'English Language'!$U$2:$U$16))) -> No | I39: =(E39*40)+F39*0.15+G39*0.2+(IF(H39="Yes",25,0)) -> 30.5 | J39: =IF(I39>87,"Excellent",IF(I39<70,"Failed",IF(I39>77,"Good","Pass"))) -> Failed
... A42: =StudendEnroll!A42 -> Ina | B42: =StudendEnroll!B42 -> Christal | C42: =StudendEnroll!C42 -> Inahr@gmail.com | D42: =StudendEnroll!D42 -> English Language | E42: =IF(D42=$N$3,(_xlfn.XLOOKUP(C42,'Physics1.DailyAttendance'!$D$2:$D$14,'Physics1.DailyAttendance'!$R$2:$R$14)),_xlfn.XLOOKUP(C42,'Maths1.DailyAttendance'!$D$2:$D$16,'Maths1.DailyAttendance'!$R$2:$R$16,_xlfn.XLOOKUP(C42,'English Language'!$D$2:$D$16,'English Language'!$R$2:$R$16))) -> 0.7 | F42: =IF(D42=$N$3,(_xlfn.XLOOKUP(C42,'Physics1.DailyAttendance'!$D$2:$D$16,'Physics1.DailyAttendance'!$S$2:$S$16)),_xlfn.XLOOKUP(C42,'Maths1.DailyAttendance'!$D$2:$D$16,'Maths1.DailyAttendance'!$S$2:$S$16,_xlfn.XLOOKUP(C42,'English Language'!D$2:$D$16,'English Language'!$S$2:$S$16))) -> 90 | G42: =IF(D42=$N$3,(_xlfn.XLOOKUP(C42,'Physics1.DailyAttendance'!$D$2:$D$16,'Physics1.DailyAttendance'!$T$2:$T$16)),_xlfn.XLOOKUP(C42,'Maths1.DailyAttendance'!$D$2:$D$16,'Maths1.DailyAttendance'!$T$2:$T$16,_xlfn.XLOOKUP(C42,'English Language'!$D$2:$D$16,'English Language'!$T$2:$T$16))) -> 87 | H42: =IF(D42=$N$3,(_xlfn.XLOOKUP(C42,'Physics1.DailyAttendance'!$D$2:$D$16,'Physics1.DailyAttendance'!$U$2:$U$16)),_xlfn.XLOOKUP(C42,'Maths1.DailyAttendance'!$D$2:$D$16,'Maths1.DailyAttendance'!$U$2:$U$16,_xlfn.XLOOKUP(C42,'English Language'!$D$2:D$16,'English Language'!$U$2:$U$16))) -> Yes | I42: =(E42*40)+F42*0.15+G42*0.2+(IF(H42="Yes",25,0)) -> 83.9 | J42: =IF(I42>87,"Excellent",IF(I42<70,"Failed",IF(I42>77,"Good","Pass"))) -> Good
A43: =StudendEnroll!A43 -> Wei | B43: =StudendEnroll!B43 -> Bao | C43: =StudendEnroll!C43 -> Weiao@gmail.com | D43: =StudendEnroll!D43 -> Physics1 | E43: =IF(D43=$N$3,(_xlfn.XLOOKUP(C43,'Physics1.DailyAttendance'!$D$2:$D$14,'Physics1.DailyAttendance'!$R$2:$R$14)),_xlfn.XLOOKUP(C43,'Maths1.DailyAttendance'!$D$2:$D$16,'Maths1.DailyAttendance'!$R$2:$R$16,_xlfn.XLOOKUP(C43,'English Language'!$D$2:$D$16,'English Language'!$R$2:$R$16))) -> 0.7 | F43: =IF(D43=$N$3,(_xlfn.XLOOKUP(C43,'Physics1.DailyAttendance'!$D$2:$D$16,'Physics1.DailyAttendance'!$S$2:$S$16)),_xlfn.XLOOKUP(C43,'Maths1.DailyAttendance'!$D$2:$D$16,'Maths1.DailyAttendance'!$S$2:$S$16,_xlfn.XLOOKUP(C43,'English Language'!D$2:$D$16,'English Language'!$S$2:$S$16))) -> 71 | G43: =IF(D43=$N$3,(_xlfn.XLOOKUP(C43,'Physics1.DailyAttendance'!$D$2:$D$16,'Physics1.DailyAttendance'!$T$2:$T$16)),_xlfn.XLOOKUP(C43,'Maths1.DailyAttendance'!$D$2:$D$16,'Maths1.DailyAttendance'!$T$2:$T$16,_xlfn.XLOOKUP(C43,'English Language'!$D$2:$D$16,'English Language'!$T$2:$T$16))) -> 79 | H43: =IF(D43=$N$3,(_xlfn.XLOOKUP(C43,'Physics1.DailyAttendance'!$D$2:$D$16,'Physics1.DailyAttendance'!$U$2:$U$16)),_xlfn.XLOOKUP(C43,'Maths1.DailyAttendance'!$D$2:$D$16,'Maths1.DailyAttendance'!$U$2:$U$16,_xlfn.XLOOKUP(C43,'English Language'!$D$2:F$16,'English Language'!$U$2:$U$16))) -> Yes | I43: =(E43*40)+F43*0.15+G43*0.2+(IF(H43="Yes",25,0)) -> 79.45 | J43: =IF(I43>87,"Excellent",IF(I43<70,"Failed",IF(I43>77,"Good","Pass"))) -> Good
